Workbook
Name PRINT_AREA_MI: #REF!

Sheet PSQuerySave1

Sheet TIMETABLE
B2: FACULTY OF ENGINEERING AND TECHNOLOGY
J4: MECH TT JAN-APR 2022
C5: CLASS | D5: BSME 3 | E5: BSME 2 | F5: BTME 05 | G5: BTME 4 | H5: BTMA 3 | I5: BTME 03 | J5: BTME 02 | K5: BTMA 02 | L5: DPL 6 | M5: DMAE 3 | N5: DNSC 3 | O5: DMEN 3 | P5: DPR 3 | Q5: DAE 3 | R5: DCE 3 | S5: DMEN 2 | T5: DMEN 2 | U5: DAE 2 | V5: DCE 2 | W5: DMAE 2 | X5: DNSC 2 | Y5: CMEN 2 | Z5: DMEN 1
B6: DAY | D6: BSME/SEP2020/J-FT | E6: BSME/AUG2021/J-FT | F6: BTME/SEP2019/S-PT | G6: BTME/AUG2021/S-PT | H6: BTMA/SEP2020/J&S-FT | I6: BTME/SEP2020/J&S-FT | J6: BTME/AUG2021/J&S-FT | K6: BTMA/AUG2021/J&S-FT | L6: DMEN/MAY2019/S-FT | M6: DMAE/SEP2020/J&S-FT | N6: DNSC/SEP2020/J&S-FT | O6: DMEN/SEP2020/J&S-FT | P6: DMEN/SEP 2020/J&S-FT | Q6: DAE/SEP2020/J-FT | R6: DCE/SEP2020/J-FT | S6: DMEN/AUG2021/J-FT | T6: DMEN/AUG2021/S-FT | U6: DAE/SEP2021/J&S-FT | V6: DCE/SEP2021/J-FT | W6: DMAE/SEP20201J&S-FT | X6: DNSC/SEP2021/J-FT | Y6: CMEN/AUG2021/S-FT | Z6: DMEN/JAN2022/S-PT | AB6: DAY
C7: TIME- | D7: Y2S1 (50) | E7: Y1S2 (55) | F7: Y3S1 (10) | G7: Y2S2 (10) | H7: Y2S1 (40) | I7: Y2S1 (65) | J7: Y1S1 (52) | K7: Y1S1 (40) | L7: 10 | M7: Y2S1 (60) | N7: Y2S1 (37) | O7: Y2S1 (50) | P7: Y2S1 | Q7: Y2S1 (46) | R7: Y2S1 (40) | S7: Y1S2 (60) | T7: Y1S2 (35) | U7: Y1S2 (50) | V7: Y1S2 (40) | W7: Y1S2 (60) | X7: Y1S2 (48) | Y7: Y1S2 (20) | Z7: Y1S1 (20)
B8: MONDAY | C8: 7.00AM | E8: APS 4102 | N8: ANS 2214 | O8: AMA 2250 | P8: AMA 2250 | R8: EME 2230 | S8: EME 2103 | U8: EEP 2150 | V8: EEP 2150 | Y8: AMA 1151 | AB8: MONDAY
E9: PHYSICS II | N9: ELECTRONIC SYST. | O9: ENG MATH III | P9: ENG MATH III | R9: MACHINES | S9: W/SHOP PRACTICE II | U9: ELECT ENG. SCIENCE | V9: ELECT ENG. SCIENCE | Y9: ENG MATH II
E10: PHY LAB | N10: MV/LAB | O10: FET 107 | P10: FET 107. | R10: FET 109. | S10: FET 316 | U10: LAB | V10: LAB. | Y10: CH
C11: 10.00AM | E11: DR. OMBOGA/LABAN | N11: BRENDA | O11: ABIERO | P11: ABIERO. | R11: BOAZ | S11: MUCHIRU | U11: ALBEITY/MWASYA | V11: ALBEITY/MWASYA | Y11: ABIERO.
C12: 10.00AM | E12: AMA 4103 | H12: TMC 4214 | I12: TMC 4213 | K12: AMA 4250 | M12: EMR 2221 | N12: ANS 2206 | O12: EME 2203 | P12: EME 2203 | Q12: EEE 2250 | S12: EME 2106 | T12: EPL2101 | U12: EME 2108 | W12: EMR 2115
E13: CALCULUS II | H13: FLUIDS I | I13: MATERIALS | K13: ALGEBRA II | M13: MARINE ELECT III | N13: CHART WORK | O13: SOLID & STRUCT I | P13: SOLID & STRUCT I | Q13: ELECTRONICS | S13: MECH SCIENCE II | T13: PLANT THEORY | U13: ENG DRAWING II | W13: W/SHOP& PRACTICE II
E14: FET108 | H14: LAB, | I14: LAB | K14: MB 16 | M14: WT 2 | N14: SC/LAB | O14: PL/LAB | P14: PL/LAB.. | Q14: ELEC LAB. | S14: FET 316. | T14: W/SHOP. | U14: DO3 | W14: SC/LAB
C15: 1.00PM | E15: MWAMUNGA | H15: MUNIALO/KIKONDE | I15: SAAD/SUDI | K15: MWAMUNGA. | M15: ALBEITY | N15: TALIB | O15: GATHUA/KIKONDE | P15: GATHUA/KIKONDE.. | Q15: MRIMA/DORIS. | S15: MASEKI. | T15: AYAGA/MWAFONDO. | U15: MAKONDE | W15: MUCHIRU
C19: 2.00PM | D19: EMC 4213 | H19: TMC 4214 | I19: TMC 4214 | J19: TMC 4105 | L19: EPL 2304 | M19: EMR 2209 | N19: ANS 2202 | O19: EME 2202 | P19: EME 2202 | Q19: EME 2203 | R19: ECH 2203 | S19: EPL2101 | T19: EAU2101 | U19: EME 2103 | V19: EME 2103 | W19: EMR 2131 | X19: ANS 2111 | Y19: EEE 1150
D20: PRODUCTION TECHN. | H20: FLUIDS I | I20: FLUIDS I | J20: FUNDAMENTAL OF MECH | L20: PLANT DRAWING II | M20: APPLIED MECH I | N20: CELESTIAL NAVIG | O20: MECHANIC OF MACH. I | P20: MECHANIC OF MACH. I | Q20: SOLID & STRUCT I | R20: UNIT OPERATION I | S20: PLANT THEORY | T20: MOTOR VEHIC THEORY | U20: W/SHOP PRACTICE II | V20: W/SHOP PRACTICE II | W20: MOTOR ENG KNOW II | X20: SEAMANSHIP II | Y20: ELECT ENG. SCIE
D21: MB O2 | H21: FET 205. | I21: FET 205 | J21: LAB | L21: SC/LAB | M21: FET 109 | N21: CH | O21: LAB.. | P21: LAB. | Q21: MB 01. | R21: MB 02 | S21: W/SHOP | T21: W/SHOP. | U21: FET 107 | V21: FET 107. | W21: FET 108 | X21: CH | Y21: MB 01
C22: 5.00PM | D22: WANGOMBE | H22: MUNIALO | I22: MUNIALO. | J22: SWALAH/MWAFONDO | L22: KEPHA | M22: BOAZ | N22: BRENDA | O22: GATHUA/LAWRENCE | P22: GATHUA/LAWRENCE. | Q22: GATHUA.. | R22: MULEWA | S22: AYAGA/MWAFONDO | T22: ABDILLAHI/KAINGU. | U22: MUCHIRU | V22: MUCHIRU. | W22: KIMATHI | X22: KUMBA | Y22: NYANGANGA
C23: 5.00PM | F23: TMC 4311 | G23: TMC 4225 | Q23: EAU 2201 | Z23: BMC 2107
F24: METROLOGY | G24: FLUIDS II | Q24: VEHICLE TECH I | Z24: COMM SKILLS
F25: FET 109 | G25: CH | Q25: MATL/LAB | Z25: ONLINE
C26: 8.00PM | F26: NYAMU.. | G26: MUNIALO | Q26: LUIS | Z26: COD MEDIA
B27: T U E S D A Y | C27: 7.00AM | D27: EMC 4211 | E27: APS 4102 | H27: EMR 4201 | I27: TEE 1221 | J27: CCI 4101 | K27: CCI 4101 | O27: EPL 2201 | Q27: EEE 2250 | S27: EAU2101 | T27: EME 2104 | U27: EPL 2101 | W27: EMR 2131 | X27: ANS 2111 | AB27: T U E S D A Y
D28: WORKSHOP TECH | E28: PHYSICS II | H28: SHIP CONST | I28: ELECTRICAL TECHN. | J28: COMP SYST & LITERACY | K28: COMPUTER SYSTEMS | O28: PLANT TECH | Q28: ELECTRONICS | S28: MOTOR VEHIC THEORY | T28: MATERIAL SCIENCE | U28: MECH PLANT THEORY | W28: MOTOR ENG KNOWL.II | X28: SEAMANSHIP II
D29: FET 107 | E29: MB 13A | H29: FET 109 | I29: ELEC LAB. | J29: FET 316 | K29: FET 316 | O29: SC/LAB | Q29: MB 13 | S29: W/SHOP | T29: MATL/LAB | U29: SC/LAB. | W29: MV/WSHOP | X29: MV/LAB
C30: 10.00AM | D30: BENSON | E30: DR. OMBOGA | H30: NYADERO | I30: KASUKU/TECHN | J30: DR,MVURYA | K30: DR. MVURYA. | O30: KEPHA | Q30: MRIMA | S30: ABDILLAHI/KAINGU | T30: KAMANZA/SUDI | U30: AYAGA. | W30: KIMATHI/MUTUKU | X30: KUMBA
C31: 10.00AM | D31: AMA 4203 | E31: EMC 4122 | H31: EMR 4201 | I31: TMC 4215 | J31: TMC 4105 | K31: ENS 4101 | L31: EPL 2305 | M31: EMR 2221 | O31: EEE 2250 | P31: EEE 2250 | Q31: EME 2202 | R31: ECI 2250 | S31: EAU 2101 | T31: EME 2108 | U31: AMA 2151 | V31: AMA 2151 | W31: EMR 2129 | Y31: EPL1102
D32: STATISTICS | E32: WORKSHOP TECH | H32: SHIP CONST | I32: W/SHOP TECH | J32: FUNDAMENTAL OF MECH | K32: MARITIME SAFETY | L32: PLANT TECH IV | M32: MARINE ELECT III | O32: ELECTRONICS | P32: ELECTRONICS | Q32: MECHANIC OF MACH. I | R32: CONTROL SYSTEM | S32: MOTOR VEHICLE THEORY | T32: ENG DRAWING II | U32: ENG MATH II | V32: ENG MATH II | W32: MARINE ELECT TECH II | Y32: PLANT TECH II
D33: FET108 | E33: FET 107 | H33: FET 109 | I33: FET 108 | J33: FET 107 | K33: MB 04. | L33: WT2 | M33: ELEC LAB | O33: MB 16B | P33: MB 16B. | Q33: LAB. | R33: MB 02 | S33: MB 04 | T33: DO3. | U33: FET 108 | V33: FET 108. | W33: WT 2 | Y33: SC/LAB
C34: 1.00PM | D34: KARAKACHA | E34: BENSON | H34: NYADERO | I34: WANGOMBE | J34: SWALAH | K34: TALIB | L34: AYAGA | M34: ALBEITY/MUSAU | O34: MRIMA, | P34: MRIMA. | Q34: GATHUA/LAWRENCE. | R34: DR. MUGA | S34: ABDILLAHI | T34: MAKONDE. | U34: MUTUNGI | V34: MUTUNGI. | W34: ALBEITY | Y34: KEPHA
C38: 2.00PM | D38: AMA 4209 | H38: EMR 4202 | I38: AMA 4105 | K38: AMA 4105 | L38: EME 2304 | M38: EMR 2207 | N38: ANS 2214 | O38: EME 2202 | P38: EME 2202 | R38: ECH 2202 | S38: EME 2108 | T38: EPL 2101 | U38: EEP 2150 | V38: EEP 2150 | W38: EMR 2120 | X38: ANS 2116 | Y38: EME 1106
D39: CALCULUS III | H39: MATERIALS & ENG | I39: CALCULUS II | K39: CALCULUS II | L39: I.O.M | M39: THERMOFLUIDS | N39: ELECTRONIC SYST. | O39: MECHANIC OF MACH. I | P39: MECHANIC OF MACH. I | R39: I.C.P 1 | S39: ENG DRAWING II | T39: MECH PLANT THEORY | U39: ELECT ENG. SCIENCE | V39: ELECT ENG. SCIENCE | W39: MARINE ENG. KNOWLE | X39: RULES OF ROAD | Y39: W/SHOP II
D40: MB 02 | H40: FET 210 | I40: MB 03 | K40: MB 16A. | L40: MB13B | M40: PL/LAB. | N40: MV/LAB | O40: FET 316 | P40: FET 316, | R40: MB 02 | S40: DO3 | T40: SC/LAB. | U40: MB 03. | V40: MB 03 | W40: MB 01 | X40: CH | Y40: WT 2
C41: 5,00PM | D41: DR. MUNYWOKI | H41: DR. BACHANI | I41: JUMA. | K41: MUTAVA. | L41: KEPHA | M41: NJERU/KIKONDE | N41: BRENDA | O41: GATHUA. | P41: GATHUA, | R41: AHMED | S41: MAKONDE | T41: AYAGA. | U41: ALBEITY. | V41: ALBEITY | W41: ABDILLAHI | X41: KUMBA | Y41: MUCHIRU
C42: 5 | F42: TMC 4317 | G42: AMA 4203 | L42: AMA 2351 | Z42: APS 2150
F43: PROFESSIONAL ETHIC | G43: STATISTICS | L43: ENG. MATH VI | Z43: PHYSICAL SCIE
F44: FET 109 | G44: FET 109 | L44: FET 207.. | Z44: FET 210
C45: 8.00PM | F45: MUNIALO | G45: KARAKACHA | L45: HARRIET.. | Z45: MULEWA
B46: W E D N E S D A Y | C46: 7,00AM | D46: BEN 4401 | H46: EMR 4202 | I46: TMC 4213 | J46: BEN 4401 | K46: EMR 4117 | M46: EMR 2207 | N46: ANS 2213 | O46: EME 2201 | P46: EME 2201 | Q46: EME 2201 | S46: EPL 2101 | T46: EEP 2150 | U46: EME 2104 | V46: EME 2104 | W46: EMR 2129 | AB46: W E D N E S D A Y
D47: ENTREPRENEURSHIP | H47: MATERIALS & ENG | I47: MATERIALS | J47: ENTREPRENEURSHIP | K47: MARINE ENG. KNOWLED. | M47: THERMOFLUIDS | N47: WATCH KEEPING | O47: THERMODYNAMICS I | P47: THERMODYNAMICS I | Q47: THERMODYNAMICS I | S47: MECH PLANT THEORY | T47: ELECTRICAL SCIENCE | U47: MATERIAL SCIENCE | V47: MATERIAL SCIENCE | W47: MARINE ELECT TECH II
D48: ONLINE | H48: LAB, | I48: MB 02 | J48: ONLINE. | K48: MB 01 | M48: CH | N48: MB 03 | O48: FET 316 | P48: FET 316. | Q48: LAB. | S48: SC/LAB | T48: EB 107 | U48: EB 107. | V48: EB 107. | W48: ELEC LAB.
...

Sheet Sheet1

Sheet ROOM ALOCACATION
N2: MOMBASA POLYTECHNIC UNIVERSITY COLLEGE
N3: (Constituent College iof JKUAT)
N4: FACULTY OF ENGINEERING AND TECHNOLOGY
N5: DEPARTMENT OF ELECTRICAL AND ELECTRONIC ENGINEERING
N6: SECOND SEMESTER-SEPT - DEC 2012 ROOM ALLOCATION CHART
C9: CLASS-> | D9: CH | E9: FET316 | F9: EA009/10 | G9: EA012 | H9: EA015 | I9: EA104 | J9: EA105 | K9: EA107 | L9: EA108 | M9: EB006 | N9: EB007 | O9: EB013 | P9: EB104 | Q9: EB105 | R9: EB107 | S9: EB109 | T9: EB110 | U9: MA111 | V9: MA209 | W9: MA212 | X9: DO3 | Y9: RM2 | Z9: MZ01 | AA9: MZ 02 | AB9: RM3 | AC9: FET203 | AD9: FET205 | AE9: FET207 | AF9: FET208 | AG9: FET209 | AH9: FET210 | AI9: CLASS->
B10: DAY | D10: CLASSROOM 1 | E10: EL. POWER LAB | F10: EL. POWER W/SH. | G10: EL. MACH. LAB | H10: EL. PRINC. LAB | I10: DAT. COM. LAB | J10: COMP. LAB | K10: MICRO. P. LAB | L10: ELECTR. LAB | M10: CLASSROOM 2 | N10: LECTURE HALL 1 | O10: CLASSROOM 3 | P10: CLASSROOM 4 | Q10: LECTURE HALL 2 | R10: CLASSROOM 5 | S10: CLASSROOM 6 | T10: LECTURE HALL 3 | U10: CONTROL LAB | V10: TELECOM. LAB | W10: ELTRO. W/SH. | X10: MECH. DRA. R. | Y10: BUILD. DR. R. | Z10: MAZRUI H. 1 | AA10: MAZRUI H. 2 | AB10: BUILD. R. 3 | AC10: MARINE | AD10: MARINE | AE10: MARINE | AF10: SIMULATION | AG10: MARINE | AH10: MARINE | AJ10: DAY
C11: TIME- | D11: 40 | E11: 70 | F11: 40 | G11: 30 | H11: 30 | I11: 20 | J11: 40 | K11: 35 | L11: 40 | M11: 35 | N11: 70 | O11: 35 | P11: 20 | Q11: 70 | R11: 35 | S11: 35 | T11: 70 | U11: 45 | V11: 45 | W11: 45 | X11: 40 | Y11: 30 | Z11: 80 | AA11: 80 | AB11: 80 | AC11: 80 | AD11: 80 | AE11: 60 | AF11: 60 | AG11: 60 | AH11: 60 | AI11: TIME-
B12: MONDAY | C12: 7 | AI12: 7 | AJ12: MONDAY
D13: =COUNTIF(TIMETABLE!D10:W10,"EA005") -> 0 | E13: =COUNTIF(TIMETABLE!D10:W10,"EA006") -> 0 | F13: =COUNTIF(TIMETABLE!D10:W10,"EA009/10") -> 0 | G13: =COUNTIF(TIMETABLE!D10:W10,"EA012") -> 0 | H13: =COUNTIF(TIMETABLE!D10:W10,"EA015") -> 0 | I13: =COUNTIF(TIMETABLE!D10:W10,"EA104") -> 0 | J13: =COUNTIF(TIMETABLE!D10:W10,"EA105") -> 0 | K13: =COUNTIF(TIMETABLE!D10:W10,"EA107") -> 0 | L13: =COUNTIF(TIMETABLE!D10:W10,"EA108") -> 0 | M13: =COUNTIF(TIMETABLE!D10:W10,"EB006") -> 0 | N13: =COUNTIF(TIMETABLE!D10:W10,"EB007") -> 0 | O13: =COUNTIF(TIMETABLE!D10:W10,"EB013") -> 0 | P13: =COUNTIF(TIMETABLE!L10:W10,"EB104") -> 0 | Q13: =COUNTIF(TIMETABLE!D10:W10,"EB105") -> 0 | R13: =COUNTIF(TIMETABLE!D10:W10,"EB107") -> 0 | S13: =COUNTIF(TIMETABLE!D10:W10,"EB109") -> 0 | T13: =COUNTIF(TIMETABLE!D10:W10,"EB110") -> 0 | U13: =COUNTIF(TIMETABLE!D10:W10,"MA111") -> 0 | V13: =COUNTIF(TIMETABLE!D10:W10,"MA209") -> 0 | W13: =COUNTIF(TIMETABLE!D10:W10,"MA212") -> 0 | X13: =COUNTIF(TIMETABLE!D10:W10,"DO3") -> 0 | Y13: =COUNTIF(TIMETABLE!D10:W10,"RM2") -> 0 | Z13: =COUNTIF(TIMETABLE!D10:W10,"MZ01") -> 0 | AA13: =COUNTIF(TIMETABLE!D10:W10,"MZ02") -> 0 | AB13: =COUNTIF(TIMETABLE!D10:W10,"RM3") -> 0 | AC13: =COUNTIF(TIMETABLE!D10:W10,"FET203") -> 0 | AD13: =COUNTIF(TIMETABLE!D10:W10,"FET205") -> 0 | AE13: =COUNTIF(TIMETABLE!D10:W10,"FET207") -> 0 | AF13: =COUNTIF(TIMETABLE!D10:W10,"FET208") -> 0 | AG13: =COUNTIF(TIMETABLE!D10:W10,"FET209") -> 0 | AH13: =COUNTIF(TIMETABLE!D10:W10,"FET210") -> 0
C14: 8 | AI14: 8
C15: 8 | AI15: 8
D16: =COUNTIF(TIMETABLE!#REF!,"EA005") -> #REF! | E16: =COUNTIF(TIMETABLE!#REF!,"EA006") -> #REF! | F16: =COUNTIF(TIMETABLE!#REF!,"EA009/10") -> #REF! | G16: =COUNTIF(TIMETABLE!#REF!,"EA012") -> #REF! | H16: =COUNTIF(TIMETABLE!#REF!,"EA015") -> #REF! | I16: =COUNTIF(TIMETABLE!#REF!,"EA104") -> #REF! | J16: =COUNTIF(TIMETABLE!#REF!,"EA105") -> #REF! | K16: =COUNTIF(TIMETABLE!#REF!,"EA107") -> #REF! | L16: =COUNTIF(TIMETABLE!#REF!,"EA108") -> #REF! | M16: =COUNTIF(TIMETABLE!#REF!,"EB006") -> #REF! | N16: =COUNTIF(TIMETABLE!#REF!,"EB007") -> #REF! | O16: =COUNTIF(TIMETABLE!#REF!,"EB013") -> #REF! | P16: =COUNTIF(TIMETABLE!#REF!,"EB104") -> #REF! | Q16: =COUNTIF(TIMETABLE!#REF!,"EB105") -> #REF! | R16: =COUNTIF(TIMETABLE!#REF!,"EB107") -> #REF! | S16: =COUNTIF(TIMETABLE!#REF!,"EB109") -> #REF! | T16: =COUNTIF(TIMETABLE!#REF!,"EB110") -> #REF! | U16: =COUNTIF(TIMETABLE!#REF!,"MA111") -> #REF! | V16: =COUNTIF(TIMETABLE!#REF!,"MA209") -> #REF! | W16: =COUNTIF(TIMETABLE!#REF!,"MA212") -> #REF! | X16: =COUNTIF(TIMETABLE!#REF!,"DO3") -> #REF! | Y16: =COUNTIF(TIMETABLE!#REF!,"RM2") -> #REF! | Z16: =COUNTIF(TIMETABLE!#REF!,"MZ01") -> #REF! | AA16: =COUNTIF(TIMETABLE!#REF!,"MZ02") -> #REF! | AB16: =COUNTIF(TIMETABLE!#REF!,"RM3") -> #REF! | AC16: =COUNTIF(TIMETABLE!#REF!,"FET203") -> #REF! | AD16: =COUNTIF(TIMETABLE!#REF!,"FET205") -> #REF! | AE16: =COUNTIF(TIMETABLE!#REF!,"FET207") -> #REF! | AF16: =COUNTIF(TIMETABLE!#REF!,"FET208") -> #REF! | AG16: =COUNTIF(TIMETABLE!#REF!,"FET209") -> #REF! | AH16: =COUNTIF(TIMETABLE!#REF!,"FET210") -> #REF!
C17: 9 | AI17: 9
C18: 9 | AI18: 9
D19: =COUNTIF(TIMETABLE!#REF!,"EA005") -> #REF! | E19: =COUNTIF(TIMETABLE!#REF!,"EA006") -> #REF! | F19: =COUNTIF(TIMETABLE!#REF!,"EA009/10") -> #REF! | G19: =COUNTIF(TIMETABLE!#REF!,"EA012") -> #REF! | H19: =COUNTIF(TIMETABLE!#REF!,"EA015") -> #REF! | I19: =COUNTIF(TIMETABLE!#REF!,"EA104") -> #REF! | J19: =COUNTIF(TIMETABLE!#REF!,"EA105") -> #REF! | K19: =COUNTIF(TIMETABLE!#REF!,"EA107") -> #REF! | L19: =COUNTIF(TIMETABLE!#REF!,"EA108") -> #REF! | M19: =COUNTIF(TIMETABLE!#REF!,"EB006") -> #REF! | N19: =COUNTIF(TIMETABLE!#REF!,"EB007") -> #REF! | O19: =COUNTIF(TIMETABLE!#REF!,"EB013") -> #REF! | P19: =COUNTIF(TIMETABLE!#REF!,"EB104") -> #REF! | Q19: =COUNTIF(TIMETABLE!#REF!,"EB105") -> #REF! | R19: =COUNTIF(TIMETABLE!#REF!,"EB107") -> #REF! | S19: =COUNTIF(TIMETABLE!#REF!,"EB109") -> #REF! | T19: =COUNTIF(TIMETABLE!#REF!,"EB110") -> #REF! | U19: =COUNTIF(TIMETABLE!#REF!,"MA111") -> #REF! | V19: =COUNTIF(TIMETABLE!#REF!,"MA209") -> #REF! | W19: =COUNTIF(TIMETABLE!#REF!,"MA212") -> #REF! | X19: =COUNTIF(TIMETABLE!#REF!,"DO3") -> #REF! | Y19: =COUNTIF(TIMETABLE!#REF!,"RM2") -> #REF! | Z19: =COUNTIF(TIMETABLE!#REF!,"MZ01") -> #REF! | AA19: =COUNTIF(TIMETABLE!#REF!,"MZ02") -> #REF! | AB19: =COUNTIF(TIMETABLE!#REF!,"RM3") -> #REF! | AC19: =COUNTIF(TIMETABLE!#REF!,"FET203") -> #REF! | AD19: =COUNTIF(TIMETABLE!#REF!,"FET205") -> #REF! | AE19: =COUNTIF(TIMETABLE!#REF!,"FET207") -> #REF! | AF19: =COUNTIF(TIMETABLE!#REF!,"FET208") -> #REF! | AG19: =COUNTIF(TIMETABLE!#REF!,"FET209") -> #REF! | AH19: =COUNTIF(TIMETABLE!#REF!,"FET210") -> #REF!
C20: 10 | AI20: 10
C21: 10 | AI21: 10
D22: =COUNTIF(TIMETABLE!D14:W14,"EA005") -> 0 | E22: =COUNTIF(TIMETABLE!D14:W14,"EA006") -> 0 | F22: =COUNTIF(TIMETABLE!D14:W14,"EA009/10") -> 0 | G22: =COUNTIF(TIMETABLE!D14:W14,"EA012") -> 0 | H22: =COUNTIF(TIMETABLE!D14:W14,"EA015") -> 0 | I22: =COUNTIF(TIMETABLE!D14:W14,"EA104") -> 0 | J22: =COUNTIF(TIMETABLE!D14:W14,"EA105") -> 0 | K22: =COUNTIF(TIMETABLE!D14:W14,"EA107") -> 0 | L22: =COUNTIF(TIMETABLE!D14:W14,"EA108") -> 0 | M22: =COUNTIF(TIMETABLE!D14:W14,"EB006") -> 0 | N22: =COUNTIF(TIMETABLE!D14:W14,"EB007") -> 0 | O22: =COUNTIF(TIMETABLE!D14:W14,"EB013") -> 0 | P22: =COUNTIF(TIMETABLE!L14:W14,"EB104") -> 0 | Q22: =COUNTIF(TIMETABLE!D14:W14,"EB105") -> 0 | R22: =COUNTIF(TIMETABLE!D14:W14,"EB107") -> 0 | S22: =COUNTIF(TIMETABLE!D14:W14,"EB109") -> 0 | T22: =COUNTIF(TIMETABLE!D14:W14,"EB110") -> 0 | U22: =COUNTIF(TIMETABLE!D14:W14,"MA111") -> 0 | V22: =COUNTIF(TIMETABLE!D14:W14,"MA209") -> 0 | W22: =COUNTIF(TIMETABLE!D14:W14,"MA212") -> 0 | X22: =COUNTIF(TIMETABLE!D14:W14,"DO3") -> 1 | Y22: =COUNTIF(TIMETABLE!D14:W14,"RM2") -> 0 | Z22: =COUNTIF(TIMETABLE!D14:W14,"MZ01") -> 0 | AA22: =COUNTIF(TIMETABLE!D14:W14,"MZ02") -> 0 | AB22: =COUNTIF(TIMETABLE!D14:W14,"RM3") -> 0 | AC22: =COUNTIF(TIMETABLE!D14:W14,"FET203") -> 0 | AD22: =COUNTIF(TIMETABLE!D14:W14,"FET205") -> 0 | AE22: =COUNTIF(TIMETABLE!D14:W14,"FET207") -> 0 | AF22: =COUNTIF(TIMETABLE!D14:W14,"FET208") -> 0 | AG22: =COUNTIF(TIMETABLE!D14:W14,"FET209") -> 0 | AH22: =COUNTIF(TIMETABLE!D14:W14,"FET210") -> 0
C23: 11 | AI23: 11
C24: 11 | AI24: 11
D25: =COUNTIF(TIMETABLE!#REF!,"EA005") -> #REF! | E25: =COUNTIF(TIMETABLE!#REF!,"EA006") -> #REF! | F25: =COUNTIF(TIMETABLE!#REF!,"EA009/10") -> #REF! | G25: =COUNTIF(TIMETABLE!#REF!,"EA012") -> #REF! | H25: =COUNTIF(TIMETABLE!#REF!,"EA015") -> #REF! | I25: =COUNTIF(TIMETABLE!#REF!,"EA104") -> #REF! | J25: =COUNTIF(TIMETABLE!#REF!,"EA105") -> #REF! | K25: =COUNTIF(TIMETABLE!#REF!,"EA107") -> #REF! | L25: =COUNTIF(TIMETABLE!#REF!,"EA108") -> #REF! | M25: =COUNTIF(TIMETABLE!#REF!,"EB006") -> #REF! | N25: =COUNTIF(TIMETABLE!#REF!,"EB007") -> #REF! | O25: =COUNTIF(TIMETABLE!#REF!,"EB013") -> #REF! | P25: =COUNTIF(TIMETABLE!#REF!,"EB104") -> #REF! | Q25: =COUNTIF(TIMETABLE!#REF!,"EB105") -> #REF! | R25: =COUNTIF(TIMETABLE!#REF!,"EB107") -> #REF! | S25: =COUNTIF(TIMETABLE!#REF!,"EB109") -> #REF! | T25: =COUNTIF(TIMETABLE!#REF!,"EB110") -> #REF! | U25: =COUNTIF(TIMETABLE!#REF!,"MA111") -> #REF! | V25: =COUNTIF(TIMETABLE!#REF!,"MA209") -> #REF! | W25: =COUNTIF(TIMETABLE!#REF!,"MA212") -> #REF! | X25: =COUNTIF(TIMETABLE!#REF!,"DO3") -> #REF! | Y25: =COUNTIF(TIMETABLE!#REF!,"RM2") -> #REF! | Z25: =COUNTIF(TIMETABLE!#REF!,"MZ01") -> #REF! | AA25: =COUNTIF(TIMETABLE!#REF!,"MZ02") -> #REF! | AB25: =COUNTIF(TIMETABLE!#REF!,"RM3") -> #REF! | AC25: =COUNTIF(TIMETABLE!#REF!,"FET203") -> #REF! | AD25: =COUNTIF(TIMETABLE!#REF!,"FET205") -> #REF! | AE25: =COUNTIF(TIMETABLE!#REF!,"FET207") -> #REF! | AF25: =COUNTIF(TIMETABLE!#REF!,"FET208") -> #REF! | AG25: =COUNTIF(TIMETABLE!#REF!,"FET209") -> #REF! | AH25: =COUNTIF(TIMETABLE!#REF!,"FET210") -> #REF!
C26: 12 | AI26: 12
C27: 12 | AI27: 12
D28: =COUNTIF(TIMETABLE!#REF!,"EA005") -> #REF! | E28: =COUNTIF(TIMETABLE!#REF!,"EA006") -> #REF! | F28: =COUNTIF(TIMETABLE!#REF!,"EA009/10") -> #REF! | G28: =COUNTIF(TIMETABLE!#REF!,"EA012") -> #REF! | H28: =COUNTIF(TIMETABLE!#REF!,"EA015") -> #REF! | I28: =COUNTIF(TIMETABLE!#REF!,"EA104") -> #REF! | J28: =COUNTIF(TIMETABLE!#REF!,"EA105") -> #REF! | K28: =COUNTIF(TIMETABLE!#REF!,"EA107") -> #REF! | L28: =COUNTIF(TIMETABLE!#REF!,"EA108") -> #REF! | M28: =COUNTIF(TIMETABLE!#REF!,"EB006") -> #REF! | N28: =COUNTIF(TIMETABLE!#REF!,"EB007") -> #REF! | O28: =COUNTIF(TIMETABLE!#REF!,"EB013") -> #REF! | P28: =COUNTIF(TIMETABLE!#REF!,"EB104") -> #REF! | Q28: =COUNTIF(TIMETABLE!#REF!,"EB105") -> #REF! | R28: =COUNTIF(TIMETABLE!#REF!,"EB107") -> #REF! | S28: =COUNTIF(TIMETABLE!#REF!,"EB109") -> #REF! | T28: =COUNTIF(TIMETABLE!#REF!,"EB110") -> #REF! | U28: =COUNTIF(TIMETABLE!#REF!,"MA111") -> #REF! | V28: =COUNTIF(TIMETABLE!#REF!,"MA209") -> #REF! | W28: =COUNTIF(TIMETABLE!#REF!,"MA212") -> #REF! | X28: =COUNTIF(TIMETABLE!#REF!,"DO3") -> #REF! | Y28: =COUNTIF(TIMETABLE!#REF!,"RM2") -> #REF! | Z28: =COUNTIF(TIMETABLE!#REF!,"MZ01") -> #REF! | AA28: =COUNTIF(TIMETABLE!#REF!,"MZ02") -> #REF! | AB28: =COUNTIF(TIMETABLE!#REF!,"RM3") -> #REF! | AC28: =COUNTIF(TIMETABLE!#REF!,"FET203") -> #REF! | AD28: =COUNTIF(TIMETABLE!#REF!,"FET205") -> #REF! | AE28: =COUNTIF(TIMETABLE!#REF!,"FET207") -> #REF! | AF28: =COUNTIF(TIMETABLE!#REF!,"FET208") -> #REF! | AG28: =COUNTIF(TIMETABLE!#REF!,"FET209") -> #REF! | AH28: =COUNTIF(TIMETABLE!#REF!,"FET210") -> #REF!
C29: 1 | AI29: 1
C33: 2 | AI33: 2
D34: =COUNTIF(TIMETABLE!D21:W21,"EA005") -> 0 | E34: =COUNTIF(TIMETABLE!D21:W21,"EA006") -> 0 | F34: =COUNTIF(TIMETABLE!D21:W21,"EA009/10") -> 0 | G34: =COUNTIF(TIMETABLE!D21:W21,"EA012") -> 0 | H34: =COUNTIF(TIMETABLE!D21:W21,"EA015") -> 0 | I34: =COUNTIF(TIMETABLE!D21:W21,"EA104") -> 0 | J34: =COUNTIF(TIMETABLE!D21:W21,"EA105") -> 0 | K34: =COUNTIF(TIMETABLE!D21:W21,"EA107") -> 0 | L34: =COUNTIF(TIMETABLE!D21:W21,"EA108") -> 0 | M34: =COUNTIF(TIMETABLE!D21:W21,"EB006") -> 0 | N34: =COUNTIF(TIMETABLE!D21:W21,"EB007") -> 0 | O34: =COUNTIF(TIMETABLE!D21:W21,"EB013") -> 0 | P34: =COUNTIF(TIMETABLE!L21:W21,"EB104") -> 0 | Q34: =COUNTIF(TIMETABLE!D21:W21,"EB105") -> 0 | R34: =COUNTIF(TIMETABLE!D21:W21,"EB107") -> 0 | S34: =COUNTIF(TIMETABLE!D21:W21,"EB109") -> 0 | T34: =COUNTIF(TIMETABLE!D21:W21,"EB110") -> 0 | U34: =COUNTIF(TIMETABLE!D21:W21,"MA111") -> 0 | V34: =COUNTIF(TIMETABLE!D21:W21,"MA209") -> 0 | W34: =COUNTIF(TIMETABLE!D21:W21,"MA212") -> 0 | X34: =COUNTIF(TIMETABLE!D21:W21,"DO3") -> 0 | Y34: =COUNTIF(TIMETABLE!D21:W21,"RM2") -> 0 | Z34: =COUNTIF(TIMETABLE!D21:W21,"MZ01") -> 0 | AA34: =COUNTIF(TIMETABLE!D21:W21,"MZ02") -> 0 | AB34: =COUNTIF(TIMETABLE!D21:W21,"RM3") -> 0 | AC34: =COUNTIF(TIMETABLE!D21:W21,"FET203") -> 0 | AD34: =COUNTIF(TIMETABLE!D21:W21,"FET205") -> 0 | AE34: =COUNTIF(TIMETABLE!D21:W21,"FET207") -> 0 | AF34: =COUNTIF(TIMETABLE!D21:W21,"FET208") -> 0 | AG34: =COUNTIF(TIMETABLE!D21:W21,"FET209") -> 0 | AH34: =COUNTIF(TIMETABLE!D21:W21,"FET210") -> 0
C35: 3 | AI35: 3
C36: 3 | AI36: 3
D37: =COUNTIF(TIMETABLE!#REF!,"EA005") -> #REF! | E37: =COUNTIF(TIMETABLE!#REF!,"EA006") -> #REF! | F37: =COUNTIF(TIMETABLE!#REF!,"EA009/10") -> #REF! | G37: =COUNTIF(TIMETABLE!#REF!,"EA012") -> #REF! | H37: =COUNTIF(TIMETABLE!#REF!,"EA015") -> #REF! | I37: =COUNTIF(TIMETABLE!#REF!,"EA104") -> #REF! | J37: =COUNTIF(TIMETABLE!#REF!,"EA105") -> #REF! | K37: =COUNTIF(TIMETABLE!#REF!,"EA107") -> #REF! | L37: =COUNTIF(TIMETABLE!#REF!,"EA108") -> #REF! | M37: =COUNTIF(TIMETABLE!#REF!,"EB006") -> #REF! | N37: =COUNTIF(TIMETABLE!#REF!,"EB007") -> #REF! | O37: =COUNTIF(TIMETABLE!#REF!,"EB013") -> #REF! | P37: =COUNTIF(TIMETABLE!#REF!,"EB104") -> #REF! | Q37: =COUNTIF(TIMETABLE!#REF!,"EB105") -> #REF! | R37: =COUNTIF(TIMETABLE!#REF!,"EB107") -> #REF! | S37: =COUNTIF(TIMETABLE!#REF!,"EB109") -> #REF! | T37: =COUNTIF(TIMETABLE!#REF!,"EB110") -> #REF! | U37: =COUNTIF(TIMETABLE!#REF!,"MA111") -> #REF! | V37: =COUNTIF(TIMETABLE!#REF!,"MA209") -> #REF! | W37: =COUNTIF(TIMETABLE!#REF!,"MA212") -> #REF! | X37: =COUNTIF(TIMETABLE!#REF!,"DO3") -> #REF! | Y37: =COUNTIF(TIMETABLE!#REF!,"RM2") -> #REF! | Z37: =COUNTIF(TIMETABLE!#REF!,"MZ01") -> #REF! | AA37: =COUNTIF(TIMETABLE!#REF!,"MZ02") -> #REF! | AB37: =COUNTIF(TIMETABLE!#REF!,"RM3") -> #REF! | AC37: =COUNTIF(TIMETABLE!#REF!,"FET203") -> #REF! | AD37: =COUNTIF(TIMETABLE!#REF!,"FET205") -> #REF! | AE37: =COUNTIF(TIMETABLE!#REF!,"FET207") -> #REF! | AF37: =COUNTIF(TIMETABLE!#REF!,"FET208") -> #REF! | AG37: =COUNTIF(TIMETABLE!#REF!,"FET209") -> #REF! | AH37: =COUNTIF(TIMETABLE!#REF!,"FET210") -> #REF!
C38: 4 | AI38: 4
C39: 4 | AI39: 4
D40: =COUNTIF(TIMETABLE!#REF!,"EA005") -> #REF! | E40: =COUNTIF(TIMETABLE!#REF!,"EA006") -> #REF! | F40: =COUNTIF(TIMETABLE!#REF!,"EA009/10") -> #REF! | G40: =COUNTIF(TIMETABLE!#REF!,"EA012") -> #REF! | H40: =COUNTIF(TIMETABLE!#REF!,"EA015") -> #REF! | I40: =COUNTIF(TIMETABLE!#REF!,"EA104") -> #REF! | J40: =COUNTIF(TIMETABLE!#REF!,"EA105") -> #REF! | K40: =COUNTIF(TIMETABLE!#REF!,"EA107") -> #REF! | L40: =COUNTIF(TIMETABLE!#REF!,"EA108") -> #REF! | M40: =COUNTIF(TIMETABLE!#REF!,"EB006") -> #REF! | N40: =COUNTIF(TIMETABLE!#REF!,"EB007") -> #REF! | O40: =COUNTIF(TIMETABLE!#REF!,"EB013") -> #REF! | P40: =COUNTIF(TIMETABLE!#REF!,"EB104") -> #REF! | Q40: =COUNTIF(TIMETABLE!#REF!,"EB105") -> #REF! | R40: =COUNTIF(TIMETABLE!#REF!,"EB107") -> #REF! | S40: =COUNTIF(TIMETABLE!#REF!,"EB109") -> #REF! | T40: =COUNTIF(TIMETABLE!#REF!,"EB110") -> #REF! | U40: =COUNTIF(TIMETABLE!#REF!,"MA111") -> #REF! | V40: =COUNTIF(TIMETABLE!#REF!,"MA209") -> #REF! | W40: =COUNTIF(TIMETABLE!#REF!,"MA212") -> #REF! | X40: =COUNTIF(TIMETABLE!#REF!,"DO3") -> #REF! | Y40: =COUNTIF(TIMETABLE!#REF!,"RM2") -> #REF! | Z40: =COUNTIF(TIMETABLE!#REF!,"MZ01") -> #REF! | AA40: =COUNTIF(TIMETABLE!#REF!,"MZ02") -> #REF! | AB40: =COUNTIF(TIMETABLE!#REF!,"RM3") -> #REF! | AC40: =COUNTIF(TIMETABLE!#REF!,"FET203") -> #REF! | AD40: =COUNTIF(TIMETABLE!#REF!,"FET205") -> #REF! | AE40: =COUNTIF(TIMETABLE!#REF!,"FET207") -> #REF! | AF40: =COUNTIF(TIMETABLE!#REF!,"FET208") -> #REF! | AG40: =COUNTIF(TIMETABLE!#REF!,"FET209") -> #REF! | AH40: =COUNTIF(TIMETABLE!#REF!,"FET210") -> #REF!
C41: 5 | AI41: 5
C42: 5 | AI42: 5
D43: =COUNTIF(TIMETABLE!#REF!,"EA005") -> #REF! | E43: =COUNTIF(TIMETABLE!#REF!,"EA006") -> #REF! | F43: =COUNTIF(TIMETABLE!#REF!,"EA009/10") -> #REF! | G43: =COUNTIF(TIMETABLE!#REF!,"EA012") -> #REF! | H43: =COUNTIF(TIMETABLE!#REF!,"EA015") -> #REF! | I43: =COUNTIF(TIMETABLE!#REF!,"EA104") -> #REF! | J43: =COUNTIF(TIMETABLE!#REF!,"EA105") -> #REF! | K43: =COUNTIF(TIMETABLE!#REF!,"EA107") -> #REF! | L43: =COUNTIF(TIMETABLE!#REF!,"EA108") -> #REF! | M43: =COUNTIF(TIMETABLE!#REF!,"EB006") -> #REF! | N43: =COUNTIF(TIMETABLE!#REF!,"EB007") -> #REF! | O43: =COUNTIF(TIMETABLE!#REF!,"EB013") -> #REF! | P43: =COUNTIF(TIMETABLE!#REF!,"EB104") -> #REF! | Q43: =COUNTIF(TIMETABLE!#REF!,"EB105") -> #REF! | R43: =COUNTIF(TIMETABLE!#REF!,"EB107") -> #REF! | S43: =COUNTIF(TIMETABLE!#REF!,"EB109") -> #REF! | T43: =COUNTIF(TIMETABLE!#REF!,"EB110") -> #REF! | U43: =COUNTIF(TIMETABLE!#REF!,"MA111") -> #REF! | V43: =COUNTIF(TIMETABLE!#REF!,"MA209") -> #REF! | W43: =COUNTIF(TIMETABLE!#REF!,"MA212") -> #REF! | X43: =COUNTIF(TIMETABLE!#REF!,"DO3") -> #REF! | Y43: =COUNTIF(TIMETABLE!#REF!,"RM2") -> #REF! | Z43: =COUNTIF(TIMETABLE!#REF!,"MZ01") -> #REF! | AA43: =COUNTIF(TIMETABLE!#REF!,"MZ02") -> #REF! | AB43: =COUNTIF(TIMETABLE!#REF!,"RM3") -> #REF! | AC43: =COUNTIF(TIMETABLE!#REF!,"FET203") -> #REF! | AD43: =COUNTIF(TIMETABLE!#REF!,"FET205") -> #REF! | AE43: =COUNTIF(TIMETABLE!#REF!,"FET207") -> #REF! | AF43: =COUNTIF(TIMETABLE!#REF!,"FET208") -> #REF! | AG43: =COUNTIF(TIMETABLE!#REF!,"FET209") -> #REF! | AH43: =COUNTIF(TIMETABLE!#REF!,"FET210") -> #REF!
C44: 6 | AI44: 6
C45: 6 | AI45: 6
D46: =COUNTIF(TIMETABLE!#REF!,"EA005") -> #REF! | E46: =COUNTIF(TIMETABLE!#REF!,"EA006") -> #REF! | F46: =COUNTIF(TIMETABLE!#REF!,"EA009/10") -> #REF! | G46: =COUNTIF(TIMETABLE!#REF!,"EA012") -> #REF! | H46: =COUNTIF(TIMETABLE!#REF!,"EA015") -> #REF! | I46: =COUNTIF(TIMETABLE!#REF!,"EA104") -> #REF! | J46: =COUNTIF(TIMETABLE!#REF!,"EA105") -> #REF! | K46: =COUNTIF(TIMETABLE!#REF!,"EA107") -> #REF! | L46: =COUNTIF(TIMETABLE!#REF!,"EA108") -> #REF! | M46: =COUNTIF(TIMETABLE!#REF!,"EB006") -> #REF! | N46: =COUNTIF(TIMETABLE!#REF!,"EB007") -> #REF! | O46: =COUNTIF(TIMETABLE!#REF!,"EB013") -> #REF! | P46: =COUNTIF(TIMETABLE!#REF!,"EB104") -> #REF! | Q46: =COUNTIF(TIMETABLE!#REF!,"EB105") -> #REF! | R46: =COUNTIF(TIMETABLE!#REF!,"EB107") -> #REF! | S46: =COUNTIF(TIMETABLE!#REF!,"EB109") -> #REF! | T46: =COUNTIF(TIMETABLE!#REF!,"EB110") -> #REF! | U46: =COUNTIF(TIMETABLE!#REF!,"MA111") -> #REF! | V46: =COUNTIF(TIMETABLE!#REF!,"MA209") -> #REF! | W46: =COUNTIF(TIMETABLE!#REF!,"MA212") -> #REF! | X46: =COUNTIF(TIMETABLE!#REF!,"DO3") -> #REF! | Y46: =COUNTIF(TIMETABLE!#REF!,"RM2") -> #REF! | Z46: =COUNTIF(TIMETABLE!#REF!,"MZ01") -> #REF! | AA46: =COUNTIF(TIMETABLE!#REF!,"MZ02") -> #REF! | AB46: =COUNTIF(TIMETABLE!#REF!,"RM3") -> #REF! | AC46: =COUNTIF(TIMETABLE!#REF!,"FET203") -> #REF! | AD46: =COUNTIF(TIMETABLE!#REF!,"FET205") -> #REF! | AE46: =COUNTIF(TIMETABLE!#REF!,"FET207") -> #REF! | AF46: =COUNTIF(TIMETABLE!#REF!,"FET208") -> #REF! | AG46: =COUNTIF(TIMETABLE!#REF!,"FET209") -> #REF! | AH46: =COUNTIF(TIMETABLE!#REF!,"FET210") -> #REF!
...

Sheet CONCATENATED
D7: CLASS-> | E7: BSC9(H) | F7: BSC9(L) | G7: BSC9E(H) | H7: BSC 9E{L} | I7: BSC8(H) | J7: BSC8(L) | K7: BSC8E(H) | L7: BSC7(H) | M7: BSC7(L) | N7: BSC7E(H) | O7: BSC6A | P7: BSC5A | Q7: BSC3 | R7: BSC1 | S7: BTEC1 | U7: DTIE6 | V7: DICE6 | W7: DICE6(BT) | X7: DICE5(BT) | Y7: DEPE5 | Z7: DEPE4 | AA7: DICE4 | AB7: DEEE2 | AC7: DEEE1 | AD7: CEPE2 | AE7: CEPE1
C8: DAY | E8: BE(S)EE/JAN2012/J+S-FT/BSEE/MAY2012/S-FT | F8: BE(S)EE/JAN2012/J+S-FT/BSEE/MAY2012/S-FT | G8: BSEE/MAY2013/S-EV(L) | H8: BSEE/MAY2013/S-EV(L) | I8: S(E)EE/SEP2012/J+S-FT/BSEE/MAY2013/S-FT | J8: S(E)EE/SEP2012/J+S-FT/BSEE/MAY2013/S-FT | K8: BSEE/MAY2014/S-PT | L8: BSEE/SEP2013/J+S-FT | M8: BSEE/SEP2013/J+S-FT | N8: BSEE/SEP2014/S-PT | O8: BSEE/MAY2014/S-FT | P8: BSEE/SEP2014/J+S-FT | Q8: BSEE/SEP2015/J+S-FT | R8: BSEE/SEP2016/J+S-FT | S8: BTEC/SEP2016/J+S-FT | U8: DTEE/SEP2014/S-FT(DTIE) | V8: DTEE/SEP2014/S-FT(DICE) | W8: DTEE/SEP2014/S-BT(2) | X8: DTEE/SEP2014/S-BT1 | Y8: DTEE/JAN2015/S-FT | Z8: DTEE/SEP2015/S-FT(DEPE) | AA8: DTEE/SEP2015/S-FT(DICE) | AB8: DTEE/MAY2016/S-FT | AC8: DTEE/SEP2016/J+S-FT | AD8: CEEE/MAY2016/S-FT | AE8: CEEE/SEP2016/S-FT | AF8: DAY
D9: TIME- | E9: 45 | F9: 37 | G9: 45 | H9: 20 | I9: 50 | J9: 50 | K9: 15 | L9: 82 | M9: 47 | N9: 15 | O9: 78 | P9: 47 | Q9: 73 | R9: 50 | S9: 40 | U9: 3 | V9: 4 | W9: 10 | X9: 10 | Y9: 15 | Z9: 8 | AA9: 8 | AB9: 10 | AC9: 40 | AD9: 8 | AE9: 10
E12: =CONCATENATE(TIMETABLE!#REF!," ","[",TIMETABLE!#REF!," ","Students","]"," ",TIMETABLE!#REF!,":"," ",TIMETABLE!#REF!," ",TIMETABLE!#REF!) -> #REF! | F12: =CONCATENATE(TIMETABLE!#REF!," ","[",TIMETABLE!#REF!," ","Students","]"," ",TIMETABLE!#REF!,":"," ",TIMETABLE!#REF!," ",TIMETABLE!#REF!) -> #REF! | G12: =CONCATENATE(TIMETABLE!#REF!," ","[",TIMETABLE!#REF!," ","Students","]"," ",TIMETABLE!#REF!,":"," ",TIMETABLE!#REF!," ",TIMETABLE!#REF!) -> #REF! | H12: =CONCATENATE(TIMETABLE!#REF!," ","[",TIMETABLE!#REF!," ","Students","]"," ",TIMETABLE!#REF!,":"," ",TIMETABLE!#REF!," ",TIMETABLE!#REF!) -> #REF! | I12: =CONCATENATE(TIMETABLE!#REF!," ","[",TIMETABLE!#REF!," ","Students","]"," ",TIMETABLE!#REF!,":"," ",TIMETABLE!#REF!," ",TIMETABLE!#REF!) -> #REF! | J12: =CONCATENATE(TIMETABLE!#REF!," ","[",TIMETABLE!#REF!," ","Students","]"," ",TIMETABLE!#REF!,":"," ",TIMETABLE!#REF!," ",TIMETABLE!#REF!) -> #REF! | K12: =CONCATENATE(TIMETABLE!#REF!," ","[",TIMETABLE!#REF!," ","Students","]"," ",TIMETABLE!#REF!,":"," ",TIMETABLE!#REF!," ",TIMETABLE!#REF!) -> #REF! | L12: =CONCATENATE(TIMETABLE!D$6," ","[",TIMETABLE!D$7," ","Students","]"," ",TIMETABLE!D8,":"," ",TIMETABLE!D11," ",TIMETABLE!D10) -> BSME/SEP2020/J-FT [Y2S1 (50) Students] : | M12: =CONCATENATE(TIMETABLE!E$6," ","[",TIMETABLE!E$7," ","Students","]"," ",TIMETABLE!E8,":"," ",TIMETABLE!E11," ",TIMETABLE!E10) -> BSME/AUG2021/J-FT [Y1S2 (55) Students] APS 4102: DR. OMBOGA/LABAN PHY LAB | N12: =CONCATENATE(TIMETABLE!#REF!," ","[",TIMETABLE!#REF!," ","Students","]"," ",TIMETABLE!#REF!,":"," ",TIMETABLE!#REF!," ",TIMETABLE!#REF!) -> #REF! | O12: =CONCATENATE(TIMETABLE!#REF!," ","[",TIMETABLE!#REF!," ","Students","]"," ",TIMETABLE!#REF!,":"," ",TIMETABLE!#REF!," ",TIMETABLE!#REF!) -> #REF! | P12: =CONCATENATE(TIMETABLE!F$6," ","[",TIMETABLE!F$7," ","Students","]"," ",TIMETABLE!F8,":"," ",TIMETABLE!F11," ",TIMETABLE!F10) -> BTME/SEP2019/S-PT [Y3S1 (10) Students] : | Q12: =CONCATENATE(TIMETABLE!G$6," ","[",TIMETABLE!G$7," ","Students","]"," ",TIMETABLE!G8,":"," ",TIMETABLE!G11," ",TIMETABLE!G10) -> BTME/AUG2021/S-PT [Y2S2 (10) Students] : | R12: =CONCATENATE(TIMETABLE!#REF!," ","[",TIMETABLE!#REF!," ","Students","]"," ",TIMETABLE!#REF!,":"," ",TIMETABLE!#REF!," ",TIMETABLE!#REF!) -> #REF! | S12: =CONCATENATE(TIMETABLE!#REF!," ","[",TIMETABLE!#REF!," ","Students","]"," ",TIMETABLE!#REF!,":"," ",TIMETABLE!#REF!," ",TIMETABLE!#REF!) -> #REF! | T12: =CONCATENATE(TIMETABLE!J$6," ","[",TIMETABLE!J$7," ","Students","]"," ",TIMETABLE!J8,":"," ",TIMETABLE!J11," ",TIMETABLE!J10) -> BTME/AUG2021/J&S-FT [Y1S1 (52) Students] : | U12: =CONCATENATE(TIMETABLE!#REF!," ","[",TIMETABLE!#REF!," ","Students","]"," ",TIMETABLE!#REF!,":"," ",TIMETABLE!#REF!," ",TIMETABLE!#REF!) -> #REF! | V12: =CONCATENATE(TIMETABLE!#REF!," ","[",TIMETABLE!#REF!," ","Students","]"," ",TIMETABLE!#REF!,":"," ",TIMETABLE!#REF!," ",TIMETABLE!#REF!) -> #REF! | W12: =CONCATENATE(TIMETABLE!#REF!," ","[",TIMETABLE!#REF!," ","Students","]"," ",TIMETABLE!#REF!,":"," ",TIMETABLE!#REF!," ",TIMETABLE!#REF!) -> #REF! | X12: =CONCATENATE(TIMETABLE!#REF!," ","[",TIMETABLE!#REF!," ","Students","]"," ",TIMETABLE!#REF!,":"," ",TIMETABLE!#REF!," ",TIMETABLE!#REF!) -> #REF! | Y12: =CONCATENATE(TIMETABLE!#REF!," ","[",TIMETABLE!#REF!," ","Students","]"," ",TIMETABLE!#REF!,":"," ",TIMETABLE!#REF!," ",TIMETABLE!#REF!) -> #REF! | Z12: =CONCATENATE(TIMETABLE!#REF!," ","[",TIMETABLE!#REF!," ","Students","]"," ",TIMETABLE!#REF!,":"," ",TIMETABLE!#REF!," ",TIMETABLE!#REF!) -> #REF! | AA12: =CONCATENATE(TIMETABLE!#REF!," ","[",TIMETABLE!#REF!," ","Students","]"," ",TIMETABLE!#REF!,":"," ",TIMETABLE!#REF!," ",TIMETABLE!#REF!) -> #REF! | AB12: =CONCATENATE(TIMETABLE!#REF!," ","[",TIMETABLE!#REF!," ","Students","]"," ",TIMETABLE!#REF!,":"," ",TIMETABLE!#REF!," ",TIMETABLE!#REF!) -> #REF! | AC12: =CONCATENATE(TIMETABLE!W$6," ","[",TIMETABLE!W$7," ","Students","]"," ",TIMETABLE!W8,":"," ",TIMETABLE!W11," ",TIMETABLE!W10) -> DMAE/SEP20201J&S-FT [Y1S2 (60) Students] : | AD12: =CONCATENATE(TIMETABLE!#REF!," ","[",TIMETABLE!#REF!," ","Students","]"," ",TIMETABLE!#REF!,":"," ",TIMETABLE!#REF!," ",TIMETABLE!#REF!) -> #REF! | AE12: =CONCATENATE(TIMETABLE!#REF!," ","[",TIMETABLE!#REF!," ","Students","]"," ",TIMETABLE!#REF!,":"," ",TIMETABLE!#REF!," ",TIMETABLE!#REF!) -> #REF!
E15: =CONCATENATE(TIMETABLE!#REF!," ","[",TIMETABLE!#REF!," ","Students","]"," ",TIMETABLE!#REF!,":"," ",TIMETABLE!#REF!," ",TIMETABLE!#REF!) -> #REF! | F15: =CONCATENATE(TIMETABLE!#REF!," ","[",TIMETABLE!#REF!," ","Students","]"," ",TIMETABLE!#REF!,":"," ",TIMETABLE!#REF!," ",TIMETABLE!#REF!) -> #REF! | G15: =CONCATENATE(TIMETABLE!#REF!," ","[",TIMETABLE!#REF!," ","Students","]"," ",TIMETABLE!#REF!,":"," ",TIMETABLE!#REF!," ",TIMETABLE!#REF!) -> #REF! | H15: =CONCATENATE(TIMETABLE!#REF!," ","[",TIMETABLE!#REF!," ","Students","]"," ",TIMETABLE!#REF!,":"," ",TIMETABLE!#REF!," ",TIMETABLE!#REF!) -> #REF! | I15: =CONCATENATE(TIMETABLE!#REF!," ","[",TIMETABLE!#REF!," ","Students","]"," ",TIMETABLE!#REF!,":"," ",TIMETABLE!#REF!," ",TIMETABLE!#REF!) -> #REF! | J15: =CONCATENATE(TIMETABLE!#REF!," ","[",TIMETABLE!#REF!," ","Students","]"," ",TIMETABLE!#REF!,":"," ",TIMETABLE!#REF!," ",TIMETABLE!#REF!) -> #REF! | K15: =CONCATENATE(TIMETABLE!#REF!," ","[",TIMETABLE!#REF!," ","Students","]"," ",TIMETABLE!#REF!,":"," ",TIMETABLE!#REF!," ",TIMETABLE!#REF!) -> #REF! | L15: =CONCATENATE(TIMETABLE!D$6," ","[",TIMETABLE!D$7," ","Students","]"," ",TIMETABLE!#REF!,":"," ",TIMETABLE!#REF!," ",TIMETABLE!#REF!) -> #REF! | M15: =CONCATENATE(TIMETABLE!E$6," ","[",TIMETABLE!E$7," ","Students","]"," ",TIMETABLE!#REF!,":"," ",TIMETABLE!#REF!," ",TIMETABLE!#REF!) -> #REF! | N15: =CONCATENATE(TIMETABLE!#REF!," ","[",TIMETABLE!#REF!," ","Students","]"," ",TIMETABLE!#REF!,":"," ",TIMETABLE!#REF!," ",TIMETABLE!#REF!) -> #REF! | O15: =CONCATENATE(TIMETABLE!#REF!," ","[",TIMETABLE!#REF!," ","Students","]"," ",TIMETABLE!#REF!,":"," ",TIMETABLE!#REF!," ",TIMETABLE!#REF!) -> #REF! | P15: =CONCATENATE(TIMETABLE!F$6," ","[",TIMETABLE!F$7," ","Students","]"," ",TIMETABLE!#REF!,":"," ",TIMETABLE!#REF!," ",TIMETABLE!#REF!) -> #REF! | Q15: =CONCATENATE(TIMETABLE!G$6," ","[",TIMETABLE!G$7," ","Students","]"," ",TIMETABLE!#REF!,":"," ",TIMETABLE!#REF!," ",TIMETABLE!#REF!) -> #REF! | R15: =CONCATENATE(TIMETABLE!#REF!," ","[",TIMETABLE!#REF!," ","Students","]"," ",TIMETABLE!#REF!,":"," ",TIMETABLE!#REF!," ",TIMETABLE!#REF!) -> #REF! | S15: =CONCATENATE(TIMETABLE!#REF!," ","[",TIMETABLE!#REF!," ","Students","]"," ",TIMETABLE!#REF!,":"," ",TIMETABLE!#REF!," ",TIMETABLE!#REF!) -> #REF! | T15: =CONCATENATE(TIMETABLE!J$6," ","[",TIMETABLE!J$7," ","Students","]"," ",TIMETABLE!#REF!,":"," ",TIMETABLE!#REF!," ",TIMETABLE!#REF!) -> #REF! | U15: =CONCATENATE(TIMETABLE!#REF!," ","[",TIMETABLE!#REF!," ","Students","]"," ",TIMETABLE!#REF!,":"," ",TIMETABLE!#REF!," ",TIMETABLE!#REF!) -> #REF! | V15: =CONCATENATE(TIMETABLE!#REF!," ","[",TIMETABLE!#REF!," ","Students","]"," ",TIMETABLE!#REF!,":"," ",TIMETABLE!#REF!," ",TIMETABLE!#REF!) -> #REF! | W15: =CONCATENATE(TIMETABLE!#REF!," ","[",TIMETABLE!#REF!," ","Students","]"," ",TIMETABLE!#REF!,":"," ",TIMETABLE!#REF!," ",TIMETABLE!#REF!) -> #REF! | X15: =CONCATENATE(TIMETABLE!#REF!," ","[",TIMETABLE!#REF!," ","Students","]"," ",TIMETABLE!#REF!,":"," ",TIMETABLE!#REF!," ",TIMETABLE!#REF!) -> #REF! | Y15: =CONCATENATE(TIMETABLE!#REF!," ","[",TIMETABLE!#REF!," ","Students","]"," ",TIMETABLE!#REF!,":"," ",TIMETABLE!#REF!," ",TIMETABLE!#REF!) -> #REF! | Z15: =CONCATENATE(TIMETABLE!#REF!," ","[",TIMETABLE!#REF!," ","Students","]"," ",TIMETABLE!#REF!,":"," ",TIMETABLE!#REF!," ",TIMETABLE!#REF!) -> #REF! | AA15: =CONCATENATE(TIMETABLE!#REF!," ","[",TIMETABLE!#REF!," ","Students","]"," ",TIMETABLE!#REF!,":"," ",TIMETABLE!#REF!," ",TIMETABLE!#REF!) -> #REF! | AB15: =CONCATENATE(TIMETABLE!#REF!," ","[",TIMETABLE!#REF!," ","Students","]"," ",TIMETABLE!#REF!,":"," ",TIMETABLE!#REF!," ",TIMETABLE!#REF!) -> #REF! | AC15: =CONCATENATE(TIMETABLE!W$6," ","[",TIMETABLE!W$7," ","Students","]"," ",TIMETABLE!#REF!,":"," ",TIMETABLE!#REF!," ",TIMETABLE!#REF!) -> #REF! | AD15: =CONCATENATE(TIMETABLE!#REF!," ","[",TIMETABLE!#REF!," ","Students","]"," ",TIMETABLE!#REF!,":"," ",TIMETABLE!#REF!," ",TIMETABLE!#REF!) -> #REF! | AE15: =CONCATENATE(TIMETABLE!#REF!," ","[",TIMETABLE!#REF!," ","Students","]"," ",TIMETABLE!#REF!,":"," ",TIMETABLE!#REF!," ",TIMETABLE!#REF!) -> #REF!
E18: =CONCATENATE(TIMETABLE!#REF!," ","[",TIMETABLE!#REF!," ","Students","]"," ",TIMETABLE!#REF!,":"," ",TIMETABLE!#REF!," ",TIMETABLE!#REF!) -> #REF! | F18: =CONCATENATE(TIMETABLE!#REF!," ","[",TIMETABLE!#REF!," ","Students","]"," ",TIMETABLE!#REF!,":"," ",TIMETABLE!#REF!," ",TIMETABLE!#REF!) -> #REF! | G18: =CONCATENATE(TIMETABLE!#REF!," ","[",TIMETABLE!#REF!," ","Students","]"," ",TIMETABLE!#REF!,":"," ",TIMETABLE!#REF!," ",TIMETABLE!#REF!) -> #REF! | H18: =CONCATENATE(TIMETABLE!#REF!," ","[",TIMETABLE!#REF!," ","Students","]"," ",TIMETABLE!#REF!,":"," ",TIMETABLE!#REF!," ",TIMETABLE!#REF!) -> #REF! | I18: =CONCATENATE(TIMETABLE!#REF!," ","[",TIMETABLE!#REF!," ","Students","]"," ",TIMETABLE!#REF!,":"," ",TIMETABLE!#REF!," ",TIMETABLE!#REF!) -> #REF! | J18: =CONCATENATE(TIMETABLE!#REF!," ","[",TIMETABLE!#REF!," ","Students","]"," ",TIMETABLE!#REF!,":"," ",TIMETABLE!#REF!," ",TIMETABLE!#REF!) -> #REF! | K18: =CONCATENATE(TIMETABLE!#REF!," ","[",TIMETABLE!#REF!," ","Students","]"," ",TIMETABLE!#REF!,":"," ",TIMETABLE!#REF!," ",TIMETABLE!#REF!) -> #REF! | L18: =CONCATENATE(TIMETABLE!D$6," ","[",TIMETABLE!D$7," ","Students","]"," ",TIMETABLE!#REF!,":"," ",TIMETABLE!#REF!," ",TIMETABLE!#REF!) -> #REF! | M18: =CONCATENATE(TIMETABLE!E$6," ","[",TIMETABLE!E$7," ","Students","]"," ",TIMETABLE!#REF!,":"," ",TIMETABLE!#REF!," ",TIMETABLE!#REF!) -> #REF! | N18: =CONCATENATE(TIMETABLE!#REF!," ","[",TIMETABLE!#REF!," ","Students","]"," ",TIMETABLE!#REF!,":"," ",TIMETABLE!#REF!," ",TIMETABLE!#REF!) -> #REF! | O18: =CONCATENATE(TIMETABLE!#REF!," ","[",TIMETABLE!#REF!," ","Students","]"," ",TIMETABLE!#REF!,":"," ",TIMETABLE!#REF!," ",TIMETABLE!#REF!) -> #REF! | P18: =CONCATENATE(TIMETABLE!F$6," ","[",TIMETABLE!F$7," ","Students","]"," ",TIMETABLE!#REF!,":"," ",TIMETABLE!#REF!," ",TIMETABLE!#REF!) -> #REF! | Q18: =CONCATENATE(TIMETABLE!G$6," ","[",TIMETABLE!G$7," ","Students","]"," ",TIMETABLE!#REF!,":"," ",TIMETABLE!#REF!," ",TIMETABLE!#REF!) -> #REF! | R18: =CONCATENATE(TIMETABLE!#REF!," ","[",TIMETABLE!#REF!," ","Students","]"," ",TIMETABLE!#REF!,":"," ",TIMETABLE!#REF!," ",TIMETABLE!#REF!) -> #REF! | S18: =CONCATENATE(TIMETABLE!#REF!," ","[",TIMETABLE!#REF!," ","Students","]"," ",TIMETABLE!#REF!,":"," ",TIMETABLE!#REF!," ",TIMETABLE!#REF!) -> #REF! | T18: =CONCATENATE(TIMETABLE!J$6," ","[",TIMETABLE!J$7," ","Students","]"," ",TIMETABLE!#REF!,":"," ",TIMETABLE!#REF!," ",TIMETABLE!#REF!) -> #REF! | U18: =CONCATENATE(TIMETABLE!#REF!," ","[",TIMETABLE!#REF!," ","Students","]"," ",TIMETABLE!#REF!,":"," ",TIMETABLE!#REF!," ",TIMETABLE!#REF!) -> #REF! | V18: =CONCATENATE(TIMETABLE!#REF!," ","[",TIMETABLE!#REF!," ","Students","]"," ",TIMETABLE!#REF!,":"," ",TIMETABLE!#REF!," ",TIMETABLE!#REF!) -> #REF! | W18: =CONCATENATE(TIMETABLE!#REF!," ","[",TIMETABLE!#REF!," ","Students","]"," ",TIMETABLE!#REF!,":"," ",TIMETABLE!#REF!," ",TIMETABLE!#REF!) -> #REF! | X18: =CONCATENATE(TIMETABLE!#REF!," ","[",TIMETABLE!#REF!," ","Students","]"," ",TIMETABLE!#REF!,":"," ",TIMETABLE!#REF!," ",TIMETABLE!#REF!) -> #REF! | Y18: =CONCATENATE(TIMETABLE!#REF!," ","[",TIMETABLE!#REF!," ","Students","]"," ",TIMETABLE!#REF!,":"," ",TIMETABLE!#REF!," ",TIMETABLE!#REF!) -> #REF! | Z18: =CONCATENATE(TIMETABLE!#REF!," ","[",TIMETABLE!#REF!," ","Students","]"," ",TIMETABLE!#REF!,":"," ",TIMETABLE!#REF!," ",TIMETABLE!#REF!) -> #REF! | AA18: =CONCATENATE(TIMETABLE!#REF!," ","[",TIMETABLE!#REF!," ","Students","]"," ",TIMETABLE!#REF!,":"," ",TIMETABLE!#REF!," ",TIMETABLE!#REF!) -> #REF! | AB18: =CONCATENATE(TIMETABLE!#REF!," ","[",TIMETABLE!#REF!," ","Students","]"," ",TIMETABLE!#REF!,":"," ",TIMETABLE!#REF!," ",TIMETABLE!#REF!) -> #REF! | AC18: =CONCATENATE(TIMETABLE!W$6," ","[",TIMETABLE!W$7," ","Students","]"," ",TIMETABLE!#REF!,":"," ",TIMETABLE!#REF!," ",TIMETABLE!#REF!) -> #REF! | AD18: =CONCATENATE(TIMETABLE!#REF!," ","[",TIMETABLE!#REF!," ","Students","]"," ",TIMETABLE!#REF!,":"," ",TIMETABLE!#REF!," ",TIMETABLE!#REF!) -> #REF! | AE18: =CONCATENATE(TIMETABLE!#REF!," ","[",TIMETABLE!#REF!," ","Students","]"," ",TIMETABLE!#REF!,":"," ",TIMETABLE!#REF!," ",TIMETABLE!#REF!) -> #REF!
E21: =CONCATENATE(TIMETABLE!#REF!," ","[",TIMETABLE!#REF!," ","Students","]"," ",TIMETABLE!#REF!,":"," ",TIMETABLE!#REF!," ",TIMETABLE!#REF!) -> #REF! | F21: =CONCATENATE(TIMETABLE!#REF!," ","[",TIMETABLE!#REF!," ","Students","]"," ",TIMETABLE!#REF!,":"," ",TIMETABLE!#REF!," ",TIMETABLE!#REF!) -> #REF! | G21: =CONCATENATE(TIMETABLE!#REF!," ","[",TIMETABLE!#REF!," ","Students","]"," ",TIMETABLE!#REF!,":"," ",TIMETABLE!#REF!," ",TIMETABLE!#REF!) -> #REF! | H21: =CONCATENATE(TIMETABLE!#REF!," ","[",TIMETABLE!#REF!," ","Students","]"," ",TIMETABLE!#REF!,":"," ",TIMETABLE!#REF!," ",TIMETABLE!#REF!) -> #REF! | I21: =CONCATENATE(TIMETABLE!#REF!," ","[",TIMETABLE!#REF!," ","Students","]"," ",TIMETABLE!#REF!,":"," ",TIMETABLE!#REF!," ",TIMETABLE!#REF!) -> #REF! | J21: =CONCATENATE(TIMETABLE!#REF!," ","[",TIMETABLE!#REF!," ","Students","]"," ",TIMETABLE!#REF!,":"," ",TIMETABLE!#REF!," ",TIMETABLE!#REF!) -> #REF! | K21: =CONCATENATE(TIMETABLE!#REF!," ","[",TIMETABLE!#REF!," ","Students","]"," ",TIMETABLE!#REF!,":"," ",TIMETABLE!#REF!," ",TIMETABLE!#REF!) -> #REF! | L21: =CONCATENATE(TIMETABLE!D$6," ","[",TIMETABLE!D$7," ","Students","]"," ",TIMETABLE!D12,":"," ",TIMETABLE!D15," ",TIMETABLE!D14) -> BSME/SEP2020/J-FT [Y2S1 (50) Students] : | M21: =CONCATENATE(TIMETABLE!E$6," ","[",TIMETABLE!E$7," ","Students","]"," ",TIMETABLE!E12,":"," ",TIMETABLE!E15," ",TIMETABLE!E14) -> BSME/AUG2021/J-FT [Y1S2 (55) Students] AMA 4103: MWAMUNGA FET108 | N21: =CONCATENATE(TIMETABLE!#REF!," ","[",TIMETABLE!#REF!," ","Students","]"," ",TIMETABLE!#REF!,":"," ",TIMETABLE!#REF!," ",TIMETABLE!#REF!) -> #REF! | O21: =CONCATENATE(TIMETABLE!#REF!," ","[",TIMETABLE!#REF!," ","Students","]"," ",TIMETABLE!#REF!,":"," ",TIMETABLE!#REF!," ",TIMETABLE!#REF!) -> #REF! | P21: =CONCATENATE(TIMETABLE!F$6," ","[",TIMETABLE!F$7," ","Students","]"," ",TIMETABLE!F12,":"," ",TIMETABLE!F15," ",TIMETABLE!F14) -> BTME/SEP2019/S-PT [Y3S1 (10) Students] : | Q21: =CONCATENATE(TIMETABLE!G$6," ","[",TIMETABLE!G$7," ","Students","]"," ",TIMETABLE!G12,":"," ",TIMETABLE!G15," ",TIMETABLE!G14) -> BTME/AUG2021/S-PT [Y2S2 (10) Students] : | R21: =CONCATENATE(TIMETABLE!#REF!," ","[",TIMETABLE!#REF!," ","Students","]"," ",TIMETABLE!#REF!,":"," ",TIMETABLE!#REF!," ",TIMETABLE!#REF!) -> #REF! | S21: =CONCATENATE(TIMETABLE!#REF!," ","[",TIMETABLE!#REF!," ","Students","]"," ",TIMETABLE!#REF!,":"," ",TIMETABLE!#REF!," ",TIMETABLE!#REF!) -> #REF! | T21: =CONCATENATE(TIMETABLE!J$6," ","[",TIMETABLE!J$7," ","Students","]"," ",TIMETABLE!J12,":"," ",TIMETABLE!J15," ",TIMETABLE!J14) -> BTME/AUG2021/J&S-FT [Y1S1 (52) Students] : | U21: =CONCATENATE(TIMETABLE!#REF!," ","[",TIMETABLE!#REF!," ","Students","]"," ",TIMETABLE!#REF!,":"," ",TIMETABLE!#REF!," ",TIMETABLE!#REF!) -> #REF! | V21: =CONCATENATE(TIMETABLE!#REF!," ","[",TIMETABLE!#REF!," ","Students","]"," ",TIMETABLE!#REF!,":"," ",TIMETABLE!#REF!," ",TIMETABLE!#REF!) -> #REF! | W21: =CONCATENATE(TIMETABLE!#REF!," ","[",TIMETABLE!#REF!," ","Students","]"," ",TIMETABLE!#REF!,":"," ",TIMETABLE!#REF!," ",TIMETABLE!#REF!) -> #REF! | X21: =CONCATENATE(TIMETABLE!#REF!," ","[",TIMETABLE!#REF!," ","Students","]"," ",TIMETABLE!#REF!,":"," ",TIMETABLE!#REF!," ",TIMETABLE!#REF!) -> #REF! | Y21: =CONCATENATE(TIMETABLE!#REF!," ","[",TIMETABLE!#REF!," ","Students","]"," ",TIMETABLE!#REF!,":"," ",TIMETABLE!#REF!," ",TIMETABLE!#REF!) -> #REF! | Z21: =CONCATENATE(TIMETABLE!#REF!," ","[",TIMETABLE!#REF!," ","Students","]"," ",TIMETABLE!#REF!,":"," ",TIMETABLE!#REF!," ",TIMETABLE!#REF!) -> #REF! | AA21: =CONCATENATE(TIMETABLE!#REF!," ","[",TIMETABLE!#REF!," ","Students","]"," ",TIMETABLE!#REF!,":"," ",TIMETABLE!#REF!," ",TIMETABLE!#REF!) -> #REF! | AB21: =CONCATENATE(TIMETABLE!#REF!," ","[",TIMETABLE!#REF!," ","Students","]"," ",TIMETABLE!#REF!,":"," ",TIMETABLE!#REF!," ",TIMETABLE!#REF!) -> #REF! | AC21: =CONCATENATE(TIMETABLE!W$6," ","[",TIMETABLE!W$7," ","Students","]"," ",TIMETABLE!W12,":"," ",TIMETABLE!W15," ",TIMETABLE!W14) -> DMAE/SEP20201J&S-FT [Y1S2 (60) Students] EMR 2115: MUCHIRU SC/LAB | AD21: =CONCATENATE(TIMETABLE!#REF!," ","[",TIMETABLE!#REF!," ","Students","]"," ",TIMETABLE!#REF!,":"," ",TIMETABLE!#REF!," ",TIMETABLE!#REF!) -> #REF! | AE21: =CONCATENATE(TIMETABLE!#REF!," ","[",TIMETABLE!#REF!," ","Students","]"," ",TIMETABLE!#REF!,":"," ",TIMETABLE!#REF!," ",TIMETABLE!#REF!) -> #REF!
E24: =CONCATENATE(TIMETABLE!#REF!," ","[",TIMETABLE!#REF!," ","Students","]"," ",TIMETABLE!#REF!,":"," ",TIMETABLE!#REF!," ",TIMETABLE!#REF!) -> #REF! | F24: =CONCATENATE(TIMETABLE!#REF!," ","[",TIMETABLE!#REF!," ","Students","]"," ",TIMETABLE!#REF!,":"," ",TIMETABLE!#REF!," ",TIMETABLE!#REF!) -> #REF! | G24: =CONCATENATE(TIMETABLE!#REF!," ","[",TIMETABLE!#REF!," ","Students","]"," ",TIMETABLE!#REF!,":"," ",TIMETABLE!#REF!," ",TIMETABLE!#REF!) -> #REF! | H24: =CONCATENATE(TIMETABLE!#REF!," ","[",TIMETABLE!#REF!," ","Students","]"," ",TIMETABLE!#REF!,":"," ",TIMETABLE!#REF!," ",TIMETABLE!#REF!) -> #REF! | I24: =CONCATENATE(TIMETABLE!#REF!," ","[",TIMETABLE!#REF!," ","Students","]"," ",TIMETABLE!#REF!,":"," ",TIMETABLE!#REF!," ",TIMETABLE!#REF!) -> #REF! | J24: =CONCATENATE(TIMETABLE!#REF!," ","[",TIMETABLE!#REF!," ","Students","]"," ",TIMETABLE!#REF!,":"," ",TIMETABLE!#REF!," ",TIMETABLE!#REF!) -> #REF! | K24: =CONCATENATE(TIMETABLE!#REF!," ","[",TIMETABLE!#REF!," ","Students","]"," ",TIMETABLE!#REF!,":"," ",TIMETABLE!#REF!," ",TIMETABLE!#REF!) -> #REF! | L24: =CONCATENATE(TIMETABLE!D$6," ","[",TIMETABLE!D$7," ","Students","]"," ",TIMETABLE!#REF!,":"," ",TIMETABLE!#REF!," ",TIMETABLE!#REF!) -> #REF! | M24: =CONCATENATE(TIMETABLE!E$6," ","[",TIMETABLE!E$7," ","Students","]"," ",TIMETABLE!#REF!,":"," ",TIMETABLE!#REF!," ",TIMETABLE!#REF!) -> #REF! | N24: =CONCATENATE(TIMETABLE!#REF!," ","[",TIMETABLE!#REF!," ","Students","]"," ",TIMETABLE!#REF!,":"," ",TIMETABLE!#REF!," ",TIMETABLE!#REF!) -> #REF! | O24: =CONCATENATE(TIMETABLE!#REF!," ","[",TIMETABLE!#REF!," ","Students","]"," ",TIMETABLE!#REF!,":"," ",TIMETABLE!#REF!," ",TIMETABLE!#REF!) -> #REF! | P24: =CONCATENATE(TIMETABLE!F$6," ","[",TIMETABLE!F$7," ","Students","]"," ",TIMETABLE!#REF!,":"," ",TIMETABLE!#REF!," ",TIMETABLE!#REF!) -> #REF! | Q24: =CONCATENATE(TIMETABLE!G$6," ","[",TIMETABLE!G$7," ","Students","]"," ",TIMETABLE!#REF!,":"," ",TIMETABLE!#REF!," ",TIMETABLE!#REF!) -> #REF! | R24: =CONCATENATE(TIMETABLE!#REF!," ","[",TIMETABLE!#REF!," ","Students","]"," ",TIMETABLE!#REF!,":"," ",TIMETABLE!#REF!," ",TIMETABLE!#REF!) -> #REF! | S24: =CONCATENATE(TIMETABLE!#REF!," ","[",TIMETABLE!#REF!," ","Students","]"," ",TIMETABLE!#REF!,":"," ",TIMETABLE!#REF!," ",TIMETABLE!#REF!) -> #REF! | T24: =CONCATENATE(TIMETABLE!J$6," ","[",TIMETABLE!J$7," ","Students","]"," ",TIMETABLE!#REF!,":"," ",TIMETABLE!#REF!," ",TIMETABLE!#REF!) -> #REF! | U24: =CONCATENATE(TIMETABLE!#REF!," ","[",TIMETABLE!#REF!," ","Students","]"," ",TIMETABLE!#REF!,":"," ",TIMETABLE!#REF!," ",TIMETABLE!#REF!) -> #REF! | V24: =CONCATENATE(TIMETABLE!#REF!," ","[",TIMETABLE!#REF!," ","Students","]"," ",TIMETABLE!#REF!,":"," ",TIMETABLE!#REF!," ",TIMETABLE!#REF!) -> #REF! | W24: =CONCATENATE(TIMETABLE!#REF!," ","[",TIMETABLE!#REF!," ","Students","]"," ",TIMETABLE!#REF!,":"," ",TIMETABLE!#REF!," ",TIMETABLE!#REF!) -> #REF! | X24: =CONCATENATE(TIMETABLE!#REF!," ","[",TIMETABLE!#REF!," ","Students","]"," ",TIMETABLE!#REF!,":"," ",TIMETABLE!#REF!," ",TIMETABLE!#REF!) -> #REF! | Y24: =CONCATENATE(TIMETABLE!#REF!," ","[",TIMETABLE!#REF!," ","Students","]"," ",TIMETABLE!#REF!,":"," ",TIMETABLE!#REF!," ",TIMETABLE!#REF!) -> #REF! | Z24: =CONCATENATE(TIMETABLE!#REF!," ","[",TIMETABLE!#REF!," ","Students","]"," ",TIMETABLE!#REF!,":"," ",TIMETABLE!#REF!," ",TIMETABLE!#REF!) -> #REF! | AA24: =CONCATENATE(TIMETABLE!#REF!," ","[",TIMETABLE!#REF!," ","Students","]"," ",TIMETABLE!#REF!,":"," ",TIMETABLE!#REF!," ",TIMETABLE!#REF!) -> #REF! | AB24: =CONCATENATE(TIMETABLE!#REF!," ","[",TIMETABLE!#REF!," ","Students","]"," ",TIMETABLE!#REF!,":"," ",TIMETABLE!#REF!," ",TIMETABLE!#REF!) -> #REF! | AC24: =CONCATENATE(TIMETABLE!W$6," ","[",TIMETABLE!W$7," ","Students","]"," ",TIMETABLE!#REF!,":"," ",TIMETABLE!#REF!," ",TIMETABLE!#REF!) -> #REF! | AD24: =CONCATENATE(TIMETABLE!#REF!," ","[",TIMETABLE!#REF!," ","Students","]"," ",TIMETABLE!#REF!,":"," ",TIMETABLE!#REF!," ",TIMETABLE!#REF!) -> #REF! | AE24: =CONCATENATE(TIMETABLE!#REF!," ","[",TIMETABLE!#REF!," ","Students","]"," ",TIMETABLE!#REF!,":"," ",TIMETABLE!#REF!," ",TIMETABLE!#REF!) -> #REF!
E27: =CONCATENATE(TIMETABLE!#REF!," ","[",TIMETABLE!#REF!," ","Students","]"," ",TIMETABLE!#REF!,":"," ",TIMETABLE!#REF!," ",TIMETABLE!#REF!) -> #REF! | F27: =CONCATENATE(TIMETABLE!#REF!," ","[",TIMETABLE!#REF!," ","Students","]"," ",TIMETABLE!#REF!,":"," ",TIMETABLE!#REF!," ",TIMETABLE!#REF!) -> #REF! | G27: =CONCATENATE(TIMETABLE!#REF!," ","[",TIMETABLE!#REF!," ","Students","]"," ",TIMETABLE!#REF!,":"," ",TIMETABLE!#REF!," ",TIMETABLE!#REF!) -> #REF! | H27: =CONCATENATE(TIMETABLE!#REF!," ","[",TIMETABLE!#REF!," ","Students","]"," ",TIMETABLE!#REF!,":"," ",TIMETABLE!#REF!," ",TIMETABLE!#REF!) -> #REF! | I27: =CONCATENATE(TIMETABLE!#REF!," ","[",TIMETABLE!#REF!," ","Students","]"," ",TIMETABLE!#REF!,":"," ",TIMETABLE!#REF!," ",TIMETABLE!#REF!) -> #REF! | J27: =CONCATENATE(TIMETABLE!#REF!," ","[",TIMETABLE!#REF!," ","Students","]"," ",TIMETABLE!#REF!,":"," ",TIMETABLE!#REF!," ",TIMETABLE!#REF!) -> #REF! | K27: =CONCATENATE(TIMETABLE!#REF!," ","[",TIMETABLE!#REF!," ","Students","]"," ",TIMETABLE!#REF!,":"," ",TIMETABLE!#REF!," ",TIMETABLE!#REF!) -> #REF! | L27: =CONCATENATE(TIMETABLE!D$6," ","[",TIMETABLE!D$7," ","Students","]"," ",TIMETABLE!#REF!,":"," ",TIMETABLE!#REF!," ",TIMETABLE!#REF!) -> #REF! | M27: =CONCATENATE(TIMETABLE!E$6," ","[",TIMETABLE!E$7," ","Students","]"," ",TIMETABLE!#REF!,":"," ",TIMETABLE!#REF!," ",TIMETABLE!#REF!) -> #REF! | N27: =CONCATENATE(TIMETABLE!#REF!," ","[",TIMETABLE!#REF!," ","Students","]"," ",TIMETABLE!#REF!,":"," ",TIMETABLE!#REF!," ",TIMETABLE!#REF!) -> #REF! | O27: =CONCATENATE(TIMETABLE!#REF!," ","[",TIMETABLE!#REF!," ","Students","]"," ",TIMETABLE!#REF!,":"," ",TIMETABLE!#REF!," ",TIMETABLE!#REF!) -> #REF! | P27: =CONCATENATE(TIMETABLE!F$6," ","[",TIMETABLE!F$7," ","Students","]"," ",TIMETABLE!#REF!,":"," ",TIMETABLE!#REF!," ",TIMETABLE!#REF!) -> #REF! | Q27: =CONCATENATE(TIMETABLE!G$6," ","[",TIMETABLE!G$7," ","Students","]"," ",TIMETABLE!#REF!,":"," ",TIMETABLE!#REF!," ",TIMETABLE!#REF!) -> #REF! | R27: =CONCATENATE(TIMETABLE!#REF!," ","[",TIMETABLE!#REF!," ","Students","]"," ",TIMETABLE!#REF!,":"," ",TIMETABLE!#REF!," ",TIMETABLE!#REF!) -> #REF! | S27: =CONCATENATE(TIMETABLE!#REF!," ","[",TIMETABLE!#REF!," ","Students","]"," ",TIMETABLE!#REF!,":"," ",TIMETABLE!#REF!," ",TIMETABLE!#REF!) -> #REF! | T27: =CONCATENATE(TIMETABLE!J$6," ","[",TIMETABLE!J$7," ","Students","]"," ",TIMETABLE!#REF!,":"," ",TIMETABLE!#REF!," ",TIMETABLE!#REF!) -> #REF! | U27: =CONCATENATE(TIMETABLE!#REF!," ","[",TIMETABLE!#REF!," ","Students","]"," ",TIMETABLE!#REF!,":"," ",TIMETABLE!#REF!," ",TIMETABLE!#REF!) -> #REF! | V27: =CONCATENATE(TIMETABLE!#REF!," ","[",TIMETABLE!#REF!," ","Students","]"," ",TIMETABLE!#REF!,":"," ",TIMETABLE!#REF!," ",TIMETABLE!#REF!) -> #REF! | W27: =CONCATENATE(TIMETABLE!#REF!," ","[",TIMETABLE!#REF!," ","Students","]"," ",TIMETABLE!#REF!,":"," ",TIMETABLE!#REF!," ",TIMETABLE!#REF!) -> #REF! | X27: =CONCATENATE(TIMETABLE!#REF!," ","[",TIMETABLE!#REF!," ","Students","]"," ",TIMETABLE!#REF!,":"," ",TIMETABLE!#REF!," ",TIMETABLE!#REF!) -> #REF! | Y27: =CONCATENATE(TIMETABLE!#REF!," ","[",TIMETABLE!#REF!," ","Students","]"," ",TIMETABLE!#REF!,":"," ",TIMETABLE!#REF!," ",TIMETABLE!#REF!) -> #REF! | Z27: =CONCATENATE(TIMETABLE!#REF!," ","[",TIMETABLE!#REF!," ","Students","]"," ",TIMETABLE!#REF!,":"," ",TIMETABLE!#REF!," ",TIMETABLE!#REF!) -> #REF! | AA27: =CONCATENATE(TIMETABLE!#REF!," ","[",TIMETABLE!#REF!," ","Students","]"," ",TIMETABLE!#REF!,":"," ",TIMETABLE!#REF!," ",TIMETABLE!#REF!) -> #REF! | AB27: =CONCATENATE(TIMETABLE!#REF!," ","[",TIMETABLE!#REF!," ","Students","]"," ",TIMETABLE!#REF!,":"," ",TIMETABLE!#REF!," ",TIMETABLE!#REF!) -> #REF! | AC27: =CONCATENATE(TIMETABLE!W$6," ","[",TIMETABLE!W$7," ","Students","]"," ",TIMETABLE!#REF!,":"," ",TIMETABLE!#REF!," ",TIMETABLE!#REF!) -> #REF! | AD27: =CONCATENATE(TIMETABLE!#REF!," ","[",TIMETABLE!#REF!," ","Students","]"," ",TIMETABLE!#REF!,":"," ",TIMETABLE!#REF!," ",TIMETABLE!#REF!) -> #REF! | AE27: =CONCATENATE(TIMETABLE!#REF!," ","[",TIMETABLE!#REF!," ","Students","]"," ",TIMETABLE!#REF!,":"," ",TIMETABLE!#REF!," ",TIMETABLE!#REF!) -> #REF!
E30: =CONCATENATE(TIMETABLE!#REF!," ","[",TIMETABLE!#REF!," ","Students","]"," ",TIMETABLE!#REF!,":"," ",TIMETABLE!#REF!," ",TIMETABLE!#REF!) -> #REF! | F30: =CONCATENATE(TIMETABLE!#REF!," ","[",TIMETABLE!#REF!," ","Students","]"," ",TIMETABLE!#REF!,":"," ",TIMETABLE!#REF!," ",TIMETABLE!#REF!) -> #REF! | G30: =CONCATENATE(TIMETABLE!#REF!," ","[",TIMETABLE!#REF!," ","Students","]"," ",TIMETABLE!#REF!,":"," ",TIMETABLE!#REF!," ",TIMETABLE!#REF!) -> #REF! | H30: =CONCATENATE(TIMETABLE!#REF!," ","[",TIMETABLE!#REF!," ","Students","]"," ",TIMETABLE!#REF!,":"," ",TIMETABLE!#REF!," ",TIMETABLE!#REF!) -> #REF! | I30: =CONCATENATE(TIMETABLE!#REF!," ","[",TIMETABLE!#REF!," ","Students","]"," ",TIMETABLE!#REF!,":"," ",TIMETABLE!#REF!," ",TIMETABLE!#REF!) -> #REF! | J30: =CONCATENATE(TIMETABLE!#REF!," ","[",TIMETABLE!#REF!," ","Students","]"," ",TIMETABLE!#REF!,":"," ",TIMETABLE!#REF!," ",TIMETABLE!#REF!) -> #REF! | K30: =CONCATENATE(TIMETABLE!#REF!," ","[",TIMETABLE!#REF!," ","Students","]"," ",TIMETABLE!#REF!,":"," ",TIMETABLE!#REF!," ",TIMETABLE!#REF!) -> #REF! | L30: =CONCATENATE(TIMETABLE!D$6," ","[",TIMETABLE!D$7," ","Students","]"," ",TIMETABLE!D16,":"," ",TIMETABLE!D18," ",TIMETABLE!D17) -> BSME/SEP2020/J-FT [Y2S1 (50) Students] : | M30: =CONCATENATE(TIMETABLE!E$6," ","[",TIMETABLE!E$7," ","Students","]"," ",TIMETABLE!E16,":"," ",TIMETABLE!E18," ",TIMETABLE!E17) -> BSME/AUG2021/J-FT [Y1S2 (55) Students] : | N30: =CONCATENATE(TIMETABLE!#REF!," ","[",TIMETABLE!#REF!," ","Students","]"," ",TIMETABLE!#REF!,":"," ",TIMETABLE!#REF!," ",TIMETABLE!#REF!) -> #REF! | O30: =CONCATENATE(TIMETABLE!#REF!," ","[",TIMETABLE!#REF!," ","Students","]"," ",TIMETABLE!#REF!,":"," ",TIMETABLE!#REF!," ",TIMETABLE!#REF!) -> #REF! | P30: =CONCATENATE(TIMETABLE!F$6," ","[",TIMETABLE!F$7," ","Students","]"," ",TIMETABLE!F16,":"," ",TIMETABLE!F18," ",TIMETABLE!F17) -> BTME/SEP2019/S-PT [Y3S1 (10) Students] : | Q30: =CONCATENATE(TIMETABLE!G$6," ","[",TIMETABLE!G$7," ","Students","]"," ",TIMETABLE!G16,":"," ",TIMETABLE!G18," ",TIMETABLE!G17) -> BTME/AUG2021/S-PT [Y2S2 (10) Students] : | R30: =CONCATENATE(TIMETABLE!#REF!," ","[",TIMETABLE!#REF!," ","Students","]"," ",TIMETABLE!#REF!,":"," ",TIMETABLE!#REF!," ",TIMETABLE!#REF!) -> #REF! | S30: =CONCATENATE(TIMETABLE!#REF!," ","[",TIMETABLE!#REF!," ","Students","]"," ",TIMETABLE!#REF!,":"," ",TIMETABLE!#REF!," ",TIMETABLE!#REF!) -> #REF! | T30: =CONCATENATE(TIMETABLE!J$6," ","[",TIMETABLE!J$7," ","Students","]"," ",TIMETABLE!J16,":"," ",TIMETABLE!J18," ",TIMETABLE!J17) -> BTME/AUG2021/J&S-FT [Y1S1 (52) Students] : | U30: =CONCATENATE(TIMETABLE!#REF!," ","[",TIMETABLE!#REF!," ","Students","]"," ",TIMETABLE!#REF!,":"," ",TIMETABLE!#REF!," ",TIMETABLE!#REF!) -> #REF! | V30: =CONCATENATE(TIMETABLE!#REF!," ","[",TIMETABLE!#REF!," ","Students","]"," ",TIMETABLE!#REF!,":"," ",TIMETABLE!#REF!," ",TIMETABLE!#REF!) -> #REF! | W30: =CONCATENATE(TIMETABLE!#REF!," ","[",TIMETABLE!#REF!," ","Students","]"," ",TIMETABLE!#REF!,":"," ",TIMETABLE!#REF!," ",TIMETABLE!#REF!) -> #REF! | X30: =CONCATENATE(TIMETABLE!#REF!," ","[",TIMETABLE!#REF!," ","Students","]"," ",TIMETABLE!#REF!,":"," ",TIMETABLE!#REF!," ",TIMETABLE!#REF!) -> #REF! | Y30: =CONCATENATE(TIMETABLE!#REF!," ","[",TIMETABLE!#REF!," ","Students","]"," ",TIMETABLE!#REF!,":"," ",TIMETABLE!#REF!," ",TIMETABLE!#REF!) -> #REF! | Z30: =CONCATENATE(TIMETABLE!#REF!," ","[",TIMETABLE!#REF!," ","Students","]"," ",TIMETABLE!#REF!,":"," ",TIMETABLE!#REF!," ",TIMETABLE!#REF!) -> #REF! | AA30: =CONCATENATE(TIMETABLE!#REF!," ","[",TIMETABLE!#REF!," ","Students","]"," ",TIMETABLE!#REF!,":"," ",TIMETABLE!#REF!," ",TIMETABLE!#REF!) -> #REF! | AB30: =CONCATENATE(TIMETABLE!#REF!," ","[",TIMETABLE!#REF!," ","Students","]"," ",TIMETABLE!#REF!,":"," ",TIMETABLE!#REF!," ",TIMETABLE!#REF!) -> #REF! | AC30: =CONCATENATE(TIMETABLE!W$6," ","[",TIMETABLE!W$7," ","Students","]"," ",TIMETABLE!W16,":"," ",TIMETABLE!W18," ",TIMETABLE!W17) -> DMAE/SEP20201J&S-FT [Y1S2 (60) Students] : | AD30: =CONCATENATE(TIMETABLE!#REF!," ","[",TIMETABLE!#REF!," ","Students","]"," ",TIMETABLE!#REF!,":"," ",TIMETABLE!#REF!," ",TIMETABLE!#REF!) -> #REF! | AE30: =CONCATENATE(TIMETABLE!#REF!," ","[",TIMETABLE!#REF!," ","Students","]"," ",TIMETABLE!#REF!,":"," ",TIMETABLE!#REF!," ",TIMETABLE!#REF!) -> #REF!
